2024-02-28 13:31:14,277 DEBUG    root            Loaded Command Group: ['gcloud', 'config']
2024-02-28 13:31:14,280 DEBUG    root            Loaded Command Group: ['gcloud', 'config', 'config_helper']
2024-02-28 13:31:14,284 DEBUG    root            Running [gcloud.config.config-helper] with arguments: [--format: "value(credential.access_token)"]
2024-02-28 13:32:34,362 DEBUG    root            timed out
Traceback (most recent call last):
  File "/usr/bin/../lib/google-cloud-sdk/lib/googlecloudsdk/core/util/retry.py", line 307, in DecoratedFunction
    return retryer.RetryOnException(f, args=args, kwargs=kwargs,
           ^^^^^^^^^^^^^^^^^^^^^^^^^^^^^^^^^^^^^^^^^^^^^^^^^^^^^
  File "/usr/bin/../lib/google-cloud-sdk/lib/googlecloudsdk/core/util/retry.py", line 197, in RetryOnException
    result, exc_info = self.RetryOnResult(
                       ^^^^^^^^^^^^^^^^^^^
  File "/usr/bin/../lib/google-cloud-sdk/lib/googlecloudsdk/core/util/retry.py", line 256, in RetryOnResult
    self._RaiseIfStop(result, state)
  File "/usr/bin/../lib/google-cloud-sdk/lib/googlecloudsdk/core/util/retry.py", line 115, in _RaiseIfStop
    raise MaxRetrialsException('Reached', result, state)
googlecloudsdk.core.util.retry.MaxRetrialsException: last_result=(None, (<class 'TimeoutError'>, TimeoutError('timed out'), <traceback object at 0x7fe8188cdec0>)), last_retrial=3, time_passed_ms=80074,time_to_wait=0

During handling of the above exception, another exception occurred:

Traceback (most recent call last):
  File "/usr/bin/../lib/google-cloud-sdk/lib/googlecloudsdk/calliope/cli.py", line 998, in Execute
    resources = calliope_command.Run(cli=self, args=args)
                ^^^^^^^^^^^^^^^^^^^^^^^^^^^^^^^^^^^^^^^^^
  File "/usr/bin/../lib/google-cloud-sdk/lib/googlecloudsdk/calliope/backend.py", line 815, in Run
    resources = command_instance.Run(args)
                ^^^^^^^^^^^^^^^^^^^^^^^^^^
  File "/usr/bin/../lib/google-cloud-sdk/lib/surface/config/config_helper.py", line 99, in Run
    cred = store.Load(use_google_auth=True)
           ^^^^^^^^^^^^^^^^^^^^^^^^^^^^^^^^
  File "/usr/bin/../lib/google-cloud-sdk/lib/googlecloudsdk/core/credentials/store.py", line 723, in Load
    cred = _Load(
           ^^^^^^
  File "/usr/bin/../lib/google-cloud-sdk/lib/googlecloudsdk/core/credentials/store.py", line 894, in _Load
    account = properties.VALUES.core.account.Get()
              ^^^^^^^^^^^^^^^^^^^^^^^^^^^^^^^^^^^^
  File "/usr/bin/../lib/google-cloud-sdk/lib/googlecloudsdk/core/properties.py", line 3917, in Get
    property_value = self.GetPropertyValue(required, validate)
                     ^^^^^^^^^^^^^^^^^^^^^^^^^^^^^^^^^^^^^^^^^
  File "/usr/bin/../lib/google-cloud-sdk/lib/googlecloudsdk/core/properties.py", line 3936, in GetPropertyValue
    property_value = _GetProperty(self,
                     ^^^^^^^^^^^^^^^^^^
  File "/usr/bin/../lib/google-cloud-sdk/lib/googlecloudsdk/core/properties.py", line 4258, in _GetProperty
    property_value = _GetPropertyWithoutDefault(prop, properties_file)
                     ^^^^^^^^^^^^^^^^^^^^^^^^^^^^^^^^^^^^^^^^^^^^^^^^^
  File "/usr/bin/../lib/google-cloud-sdk/lib/googlecloudsdk/core/properties.py", line 4313, in _GetPropertyWithoutDefault
    value = callback()
            ^^^^^^^^^^
  File "/usr/bin/../lib/google-cloud-sdk/lib/googlecloudsdk/core/credentials/store.py", line 238, in GetAccount
    return c_gce.Metadata().DefaultAccount()
           ^^^^^^^^^^^^^^^^^^^^^^^^^^^^^^^^^
  File "/usr/bin/../lib/google-cloud-sdk/lib/googlecloudsdk/core/credentials/gce.py", line 94, in Inner
    return f(self, *args, **kwargs)
           ^^^^^^^^^^^^^^^^^^^^^^^^
  File "/usr/bin/../lib/google-cloud-sdk/lib/googlecloudsdk/core/credentials/gce.py", line 135, in DefaultAccount
    account = _ReadNoProxyWithCleanFailures(
              ^^^^^^^^^^^^^^^^^^^^^^^^^^^^^^
  File "/usr/bin/../lib/google-cloud-sdk/lib/googlecloudsdk/core/util/retry.py", line 312, in DecoratedFunction
    exceptions.reraise(to_reraise[1], tb=to_reraise[2])
  File "/usr/bin/../lib/google-cloud-sdk/lib/googlecloudsdk/core/exceptions.py", line 146, in reraise
    six.reraise(type(exc_value), exc_value, tb)
  File "/usr/bin/../lib/google-cloud-sdk/lib/third_party/six/__init__.py", line 719, in reraise
    raise value
  File "/usr/bin/../lib/google-cloud-sdk/lib/googlecloudsdk/core/util/retry.py", line 182, in TryFunc
    return func(*args, **kwargs), None
           ^^^^^^^^^^^^^^^^^^^^^
  File "/usr/bin/../lib/google-cloud-sdk/lib/googlecloudsdk/core/credentials/gce.py", line 60, in _ReadNoProxyWithCleanFailures
    return gce_read.ReadNoProxy(uri, timeout)
           ^^^^^^^^^^^^^^^^^^^^^^^^^^^^^^^^^^
  File "/usr/bin/../lib/google-cloud-sdk/lib/googlecloudsdk/core/credentials/gce_read.py", line 63, in ReadNoProxy
    result = urllib.request.build_opener(urllib.request.ProxyHandler({})).open(
             ^^^^^^^^^^^^^^^^^^^^^^^^^^^^^^^^^^^^^^^^^^^^^^^^^^^^^^^^^^^^^^^^^^
  File "/usr/lib/google-cloud-sdk/platform/bundledpythonunix/lib/python3.11/urllib/request.py", line 519, in open
    response = self._open(req, data)
               ^^^^^^^^^^^^^^^^^^^^^
  File "/usr/lib/google-cloud-sdk/platform/bundledpythonunix/lib/python3.11/urllib/request.py", line 536, in _open
    result = self._call_chain(self.handle_open, protocol, protocol +
             ^^^^^^^^^^^^^^^^^^^^^^^^^^^^^^^^^^^^^^^^^^^^^^^^^^^^^^^
  File "/usr/lib/google-cloud-sdk/platform/bundledpythonunix/lib/python3.11/urllib/request.py", line 496, in _call_chain
    result = func(*args)
             ^^^^^^^^^^^
  File "/usr/lib/google-cloud-sdk/platform/bundledpythonunix/lib/python3.11/urllib/request.py", line 1377, in http_open
    return self.do_open(http.client.HTTPConnection, req)
           ^^^^^^^^^^^^^^^^^^^^^^^^^^^^^^^^^^^^^^^^^^^^^
  File "/usr/lib/google-cloud-sdk/platform/bundledpythonunix/lib/python3.11/urllib/request.py", line 1352, in do_open
    r = h.getresponse()
        ^^^^^^^^^^^^^^^
  File "/usr/lib/google-cloud-sdk/platform/bundledpythonunix/lib/python3.11/http/client.py", line 1386, in getresponse
    response.begin()
  File "/usr/lib/google-cloud-sdk/platform/bundledpythonunix/lib/python3.11/http/client.py", line 325, in begin
    version, status, reason = self._read_status()
                              ^^^^^^^^^^^^^^^^^^^
  File "/usr/lib/google-cloud-sdk/platform/bundledpythonunix/lib/python3.11/http/client.py", line 286, in _read_status
    line = str(self.fp.readline(_MAXLINE + 1), "iso-8859-1")
               ^^^^^^^^^^^^^^^^^^^^^^^^^^^^^^
  File "/usr/lib/google-cloud-sdk/platform/bundledpythonunix/lib/python3.11/socket.py", line 706, in readinto
    return self._sock.recv_into(b)
           ^^^^^^^^^^^^^^^^^^^^^^^
TimeoutError: timed out
2024-02-28 13:32:34,371 ERROR    ___FILE_ONLY___ BEGIN CRASH STACKTRACE
Traceback (most recent call last):
  File "/usr/bin/../lib/google-cloud-sdk/lib/googlecloudsdk/core/util/retry.py", line 307, in DecoratedFunction
    return retryer.RetryOnException(f, args=args, kwargs=kwargs,
           ^^^^^^^^^^^^^^^^^^^^^^^^^^^^^^^^^^^^^^^^^^^^^^^^^^^^^
  File "/usr/bin/../lib/google-cloud-sdk/lib/googlecloudsdk/core/util/retry.py", line 197, in RetryOnException
    result, exc_info = self.RetryOnResult(
                       ^^^^^^^^^^^^^^^^^^^
  File "/usr/bin/../lib/google-cloud-sdk/lib/googlecloudsdk/core/util/retry.py", line 256, in RetryOnResult
    self._RaiseIfStop(result, state)
  File "/usr/bin/../lib/google-cloud-sdk/lib/googlecloudsdk/core/util/retry.py", line 115, in _RaiseIfStop
    raise MaxRetrialsException('Reached', result, state)
googlecloudsdk.core.util.retry.MaxRetrialsException: last_result=(None, (<class 'TimeoutError'>, TimeoutError('timed out'), <traceback object at 0x7fe8188cdec0>)), last_retrial=3, time_passed_ms=80074,time_to_wait=0

During handling of the above exception, another exception occurred:

Traceback (most recent call last):
  File "/usr/bin/../lib/google-cloud-sdk/lib/googlecloudsdk/command_lib/crash_handling.py", line 199, in Wrapper
    target_function(*args, **kwargs)
  File "/usr/bin/../lib/google-cloud-sdk/lib/googlecloudsdk/gcloud_main.py", line 186, in main
    gcloud_cli.Execute()
  File "/usr/bin/../lib/google-cloud-sdk/lib/googlecloudsdk/calliope/cli.py", line 1024, in Execute
    self._HandleAllErrors(exc, command_path_string, specified_arg_names)
  File "/usr/bin/../lib/google-cloud-sdk/lib/googlecloudsdk/calliope/cli.py", line 1061, in _HandleAllErrors
    exceptions.HandleError(exc, command_path_string, self.__known_error_handler)
  File "/usr/bin/../lib/google-cloud-sdk/lib/googlecloudsdk/calliope/exceptions.py", line 557, in HandleError
    core_exceptions.reraise(exc)
  File "/usr/bin/../lib/google-cloud-sdk/lib/googlecloudsdk/core/exceptions.py", line 146, in reraise
    six.reraise(type(exc_value), exc_value, tb)
  File "/usr/bin/../lib/google-cloud-sdk/lib/third_party/six/__init__.py", line 719, in reraise
    raise value
  File "/usr/bin/../lib/google-cloud-sdk/lib/googlecloudsdk/calliope/cli.py", line 998, in Execute
    resources = calliope_command.Run(cli=self, args=args)
                ^^^^^^^^^^^^^^^^^^^^^^^^^^^^^^^^^^^^^^^^^
  File "/usr/bin/../lib/google-cloud-sdk/lib/googlecloudsdk/calliope/backend.py", line 815, in Run
    resources = command_instance.Run(args)
                ^^^^^^^^^^^^^^^^^^^^^^^^^^
  File "/usr/bin/../lib/google-cloud-sdk/lib/surface/config/config_helper.py", line 99, in Run
    cred = store.Load(use_google_auth=True)
           ^^^^^^^^^^^^^^^^^^^^^^^^^^^^^^^^
  File "/usr/bin/../lib/google-cloud-sdk/lib/googlecloudsdk/core/credentials/store.py", line 723, in Load
    cred = _Load(
           ^^^^^^
  File "/usr/bin/../lib/google-cloud-sdk/lib/googlecloudsdk/core/credentials/store.py", line 894, in _Load
    account = properties.VALUES.core.account.Get()
              ^^^^^^^^^^^^^^^^^^^^^^^^^^^^^^^^^^^^
  File "/usr/bin/../lib/google-cloud-sdk/lib/googlecloudsdk/core/properties.py", line 3917, in Get
    property_value = self.GetPropertyValue(required, validate)
                     ^^^^^^^^^^^^^^^^^^^^^^^^^^^^^^^^^^^^^^^^^
  File "/usr/bin/../lib/google-cloud-sdk/lib/googlecloudsdk/core/properties.py", line 3936, in GetPropertyValue
    property_value = _GetProperty(self,
                     ^^^^^^^^^^^^^^^^^^
  File "/usr/bin/../lib/google-cloud-sdk/lib/googlecloudsdk/core/properties.py", line 4258, in _GetProperty
    property_value = _GetPropertyWithoutDefault(prop, properties_file)
                     ^^^^^^^^^^^^^^^^^^^^^^^^^^^^^^^^^^^^^^^^^^^^^^^^^
  File "/usr/bin/../lib/google-cloud-sdk/lib/googlecloudsdk/core/properties.py", line 4313, in _GetPropertyWithoutDefault
    value = callback()
            ^^^^^^^^^^
  File "/usr/bin/../lib/google-cloud-sdk/lib/googlecloudsdk/core/credentials/store.py", line 238, in GetAccount
    return c_gce.Metadata().DefaultAccount()
           ^^^^^^^^^^^^^^^^^^^^^^^^^^^^^^^^^
  File "/usr/bin/../lib/google-cloud-sdk/lib/googlecloudsdk/core/credentials/gce.py", line 94, in Inner
    return f(self, *args, **kwargs)
           ^^^^^^^^^^^^^^^^^^^^^^^^
  File "/usr/bin/../lib/google-cloud-sdk/lib/googlecloudsdk/core/credentials/gce.py", line 135, in DefaultAccount
    account = _ReadNoProxyWithCleanFailures(
              ^^^^^^^^^^^^^^^^^^^^^^^^^^^^^^
  File "/usr/bin/../lib/google-cloud-sdk/lib/googlecloudsdk/core/util/retry.py", line 312, in DecoratedFunction
    exceptions.reraise(to_reraise[1], tb=to_reraise[2])
  File "/usr/bin/../lib/google-cloud-sdk/lib/googlecloudsdk/core/exceptions.py", line 146, in reraise
    six.reraise(type(exc_value), exc_value, tb)
  File "/usr/bin/../lib/google-cloud-sdk/lib/third_party/six/__init__.py", line 719, in reraise
    raise value
  File "/usr/bin/../lib/google-cloud-sdk/lib/googlecloudsdk/core/util/retry.py", line 182, in TryFunc
    return func(*args, **kwargs), None
           ^^^^^^^^^^^^^^^^^^^^^
  File "/usr/bin/../lib/google-cloud-sdk/lib/googlecloudsdk/core/credentials/gce.py", line 60, in _ReadNoProxyWithCleanFailures
    return gce_read.ReadNoProxy(uri, timeout)
           ^^^^^^^^^^^^^^^^^^^^^^^^^^^^^^^^^^
  File "/usr/bin/../lib/google-cloud-sdk/lib/googlecloudsdk/core/credentials/gce_read.py", line 63, in ReadNoProxy
    result = urllib.request.build_opener(urllib.request.ProxyHandler({})).open(
             ^^^^^^^^^^^^^^^^^^^^^^^^^^^^^^^^^^^^^^^^^^^^^^^^^^^^^^^^^^^^^^^^^^
  File "/usr/lib/google-cloud-sdk/platform/bundledpythonunix/lib/python3.11/urllib/request.py", line 519, in open
    response = self._open(req, data)
               ^^^^^^^^^^^^^^^^^^^^^
  File "/usr/lib/google-cloud-sdk/platform/bundledpythonunix/lib/python3.11/urllib/request.py", line 536, in _open
    result = self._call_chain(self.handle_open, protocol, protocol +
             ^^^^^^^^^^^^^^^^^^^^^^^^^^^^^^^^^^^^^^^^^^^^^^^^^^^^^^^
  File "/usr/lib/google-cloud-sdk/platform/bundledpythonunix/lib/python3.11/urllib/request.py", line 496, in _call_chain
    result = func(*args)
             ^^^^^^^^^^^
  File "/usr/lib/google-cloud-sdk/platform/bundledpythonunix/lib/python3.11/urllib/request.py", line 1377, in http_open
    return self.do_open(http.client.HTTPConnection, req)
           ^^^^^^^^^^^^^^^^^^^^^^^^^^^^^^^^^^^^^^^^^^^^^
  File "/usr/lib/google-cloud-sdk/platform/bundledpythonunix/lib/python3.11/urllib/request.py", line 1352, in do_open
    r = h.getresponse()
        ^^^^^^^^^^^^^^^
  File "/usr/lib/google-cloud-sdk/platform/bundledpythonunix/lib/python3.11/http/client.py", line 1386, in getresponse
    response.begin()
  File "/usr/lib/google-cloud-sdk/platform/bundledpythonunix/lib/python3.11/http/client.py", line 325, in begin
    version, status, reason = self._read_status()
                              ^^^^^^^^^^^^^^^^^^^
  File "/usr/lib/google-cloud-sdk/platform/bundledpythonunix/lib/python3.11/http/client.py", line 286, in _read_status
    line = str(self.fp.readline(_MAXLINE + 1), "iso-8859-1")
               ^^^^^^^^^^^^^^^^^^^^^^^^^^^^^^
  File "/usr/lib/google-cloud-sdk/platform/bundledpythonunix/lib/python3.11/socket.py", line 706, in readinto
    return self._sock.recv_into(b)
           ^^^^^^^^^^^^^^^^^^^^^^^
TimeoutError: timed out
2024-02-28 13:32:34,376 ERROR    root            gcloud crashed (TimeoutError): timed out
2024-02-28 13:32:34,376 INFO     ___FILE_ONLY___ 
If you would like to report this issue, please run the following command:

2024-02-28 13:32:34,376 INFO     ___FILE_ONLY___   gcloud feedback

2024-02-28 13:32:34,377 INFO     ___FILE_ONLY___ 
To check gcloud for common problems, please run the following command:

2024-02-28 13:32:34,377 INFO     ___FILE_ONLY___   gcloud info --run-diagnostics

